import unittest
import company


class TestEmployee(unittest.TestCase):
    def setUp(self):
        self.dan = company.Employee("Michael", "Jordan", 10000)

# 4 Test should pass

    def test_give_raise_default_works(self):
        self.assertEqual(self.dan.give_raise(), "After a raise of 5000, you have 15000.")

    def test_give_raise_works_with_positive_integer(self):
        self.assertEqual(self.dan.give_raise(10000), "After a raise of 10000, you have 20000.")

    def test_give_raise_negative_raise_error(self):
        self.assertEqual(self.dan.give_raise(-100), "-100 is NOT a raise!")

    def test_give_raise_non_integer_error(self):
        self.assertEqual(self.dan.give_raise("hundred"), "You need to enter a positive integer!")

# This is the failed test.

    # def test_give_raise_zero_message(self):
    #     self.assertEqual(self.dan.give_raise(0), "There is no raise!")


# TestEmployee()
unittest.main()

# if __name__ == 'test_employee':
#     print("Mr. Martin")
#     t = TestEmployee()
#     unittest.main(t)


# if only with unittest.main()
'''
Testing started at 19:54 ...
/usr/local/bin/python3.7 "/Applications/PyCharm CE.app/Contents/helpers/pycharm/_jb_unittest_runner.py" --path /Users/Ming/Documents/CodingNomads/python-onsite/week_03/03_testing/test_employee.py

----------------------------------------------------------------------
Launching unittests with arguments python -m unittest /Users/Ming/Documents/CodingNomads/python-onsite/week_03/03_testing/test_employee.py in /Users/Ming/Documents/CodingNomads/python-onsite/week_03/03_testing
Ran 0 tests in 0.000s


OK

Process finished with exit code 0
'''

# with the proper __main__
'''
Testing started at 19:55 ...
/usr/local/bin/python3.7 "/Applications/PyCharm CE.app/Contents/helpers/pycharm/_jb_unittest_runner.py" --path /Users/Ming/Documents/CodingNomads/python-onsite/week_03/03_testing/test_employee.py
Launching unittests with arguments python -m unittest /Users/Ming/Documents/CodingNomads/python-onsite/week_03/03_testing/test_employee.py in /Users/Ming/Documents/CodingNomads/python-onsite/week_03/03_testing


Ran 4 tests in 0.002s

OK

Process finished with exit code 0
'''

# without any main()
'''
Testing started at 19:57 ...
/usr/local/bin/python3.7 "/Applications/PyCharm CE.app/Contents/helpers/pycharm/_jb_unittest_runner.py" --path /Users/Ming/Documents/CodingNomads/python-onsite/week_03/03_testing/test_employee.py


Ran 4 tests in 0.002s


OK
Launching unittests with arguments python -m unittest /Users/Ming/Documents/CodingNomads/python-onsite/week_03/03_testing/test_employee.py in /Users/Ming/Documents/CodingNomads/python-onsite/week_03/03_testing
Process finished with exit code 0
'''
